Workbook
Name BASE: '[1]BASE VENTAS'!$A:$E
Name ENTRADAS: ENTRADAS!$B:$F
Name VARMAN: #REF!

Sheet ENTRADAS
A1: FECHA | B1: CÓDIGO | C1: DESCRIPCIÓN | D1: BODEGA | E1: CANTIDAD | F1: VLR COMPRA | G1: VLR TOTAL COMPRA | H1: VLR VENTA
A2: 46150 | B2: VRM001 | C2: ADIDAS ADISTAR NEGRO BLANCO | D2: VARMAN | E2: 11 | F2: 85000 | G2: =+E2*F2 -> 935000 | H2: =+F2+20000 -> 105000
A3: 46150 | B3: VRM002 | C3: ADIDAS ADIZERO SL CAFÉ AZUL | D3: VARMAN | E3: 11 | F3: 85000 | G3: =+E3*F3 -> 935000 | H3: =+F3+20000 -> 105000
A4: 46150 | B4: VRM003 | C4: ADIDAS BOUNCE GRIS | D4: VARMAN | E4: 12 | F4: 80000 | G4: =+E4*F4 -> 960000 | H4: =+F4+20000 -> 100000
A5: 46150 | B5: VRM004 | C5: ADIDAS GAZELLE BEIGE VERDE | D5: VARMAN | E5: 5 | F5: 80000 | G5: =+E5*F5 -> 400000 | H5: =+F5+20000 -> 100000
A6: 46150 | B6: VRM005 | C6: ADIDAS LED AZUL NEGRO | D6: VARMAN | E6: 13 | F6: 85000 | G6: =+E6*F6 -> 1105000 | H6: =+F6+20000 -> 105000
A7: 46150 | B7: VRM006 | C7: ADIDAS NAS TASE BLANCO AZUL | D7: VARMAN | E7: 23 | F7: 80000 | G7: =+E7*F7 -> 1840000 | H7: =+F7+20000 -> 100000
A8: 46150 | B8: VRM007 | C8: ADIDAS PUREBOOST NEGRO BLANCO | D8: VARMAN | E8: 36 | F8: 85000 | G8: =+E8*F8 -> 3060000 | H8: =+F8+20000 -> 105000
A9: 46150 | B9: VRM008 | C9: ADIDAS SAMBA BLANCA CLASICA | D9: VARMAN | E9: 23 | F9: 70000 | G9: =+E9*F9 -> 1610000 | H9: =+F9+20000 -> 90000
A10: 46150 | B10: VRM009 | C10: ADIDAS SAMBA CLASICA NEGRO | D10: VARMAN | E10: 22 | F10: 70000 | G10: =+E10*F10 -> 1540000 | H10: =+F10+20000 -> 90000
A11: 46150 | B11: VRM010 | C11: ADIDAS SAMBA PLATAFORMA BLANCO VERDE | D11: VARMAN | E11: 9 | F11: 80000 | G11: =+E11*F11 -> 720000 | H11: =+F11+20000 -> 100000
A12: 46150 | B12: VRM011 | C12: ADIDAS SPEZIAL VERDE ROSADO | D12: VARMAN | E12: 7 | F12: 80000 | G12: =+E12*F12 -> 560000 | H12: =+F12+20000 -> 100000
A13: 46150 | B13: VRM012 | C13: ADIDAS SPEZIAL VINOTINTO | D13: VARMAN | E13: 10 | F13: 85000 | G13: =+E13*F13 -> 850000 | H13: =+F13+20000 -> 105000
... A23: 46150 | B23: VRM022 | C23: DIESEL NEGRO BLANCO | D23: VARMAN | E23: 2 | F23: 70000 | G23: =+E23*F23 -> 140000 | H23: =+F23+20000 -> 90000
A24: 46150 | B24: VRM023 | C24: FILA RAY BEIGE MORADO | D24: VARMAN | E24: 15 | F24: =2040000/24 -> 85000 | G24: =+E24*F24 -> 1275000 | H24: =+F24+20000 -> 105000
A25: 46150 | B25: VRM024 | C25: JORDAN 1 NEGRO DORADO | D25: VARMAN | E25: 2 | F25: 85000 | G25: =+E25*F25 -> 170000 | H25: =+F25+20000 -> 105000
A26: 46150 | B26: VRM025 | C26: JORDAN 1 SPACEJAM | D26: VARMAN | E26: 17 | F26: 85000 | G26: =+E26*F26 -> 1445000 | H26: =+F26+20000 -> 105000
A27: 46150 | B27: VRM026 | C27: JORDAN 4 FROZEN | D27: VARMAN | E27: 4 | F27: 80000 | G27: =+E27*F27 -> 320000 | H27: =+F27+20000 -> 100000
A28: 46150 | B28: VRM027 | C28: JORDAN 4 FULL NEGRA | D28: VARMAN | E28: 23 | F28: 85000 | G28: =+E28*F28 -> 1955000 | H28: =+F28+20000 -> 105000
A29: 46150 | B29: VRM028 | C29: JORDAN CADENCE BLANCO ROJO | D29: VARMAN | E29: 21 | F29: 90000 | G29: =+E29*F29 -> 1890000 | H29: =+F29+20000 -> 110000
A30: 46150 | B30: VRM029 | C30: JORDAN CADENCE GRIS AMARILLO | D30: VARMAN | E30: 5 | F30: 80000 | G30: =+E30*F30 -> 400000 | H30: =+F30+20000 -> 100000
A31: 46150 | B31: VRM030 | C31: JORDAN CADENCE GRIS ROJO | D31: VARMAN | E31: 10 | F31: 80000 | G31: =+E31*F31 -> 800000 | H31: =+F31+20000 -> 100000
A32: 46150 | B32: VRM031 | C32: JORDAN RETRO 4 NEGRO AMARILLO | D32: VARMAN | E32: 23 | F32: 85000 | G32: =+E32*F32 -> 1955000 | H32: =+F32+20000 -> 105000
A33: 46150 | B33: VRM032 | C33: LOUIS VUITTON G5 GRIS | D33: VARMAN | E33: 39 | F33: 150000 | G33: =+E33*F33 -> 5850000 | H33: 200000
A34: 46150 | B34: VRM033 | C34: LOUIS VUITTON G5 NEGRA | D34: VARMAN | E34: 38 | F34: 150000 | G34: =+E34*F34 -> 5700000 | H34: 200000
A35: 46150 | B35: VRM034 | C35: NEW BALANCE 1000 ROSADO | D35: VARMAN | E35: 6 | F35: 85000 | G35: =+E35*F35 -> 510000 | H35: =+F35+20000 -> 105000
A36: 46150 | B36: VRM035 | C36: NEW BALANCE 1000 VERDE | D36: VARMAN | E36: 11 | F36: 66000 | G36: =+E36*F36 -> 726000 | H36: 100000
A37: 46150 | B37: VRM036 | C37: NEW BALANCE 327 AZUL | D37: VARMAN | E37: 2 | F37: 80000 | G37: =+E37*F37 -> 160000 | H37: =+F37+20000 -> 100000
A38: 46150 | B38: VRM037 | C38: NEW BALANCE 530 BLANCO AZUL | D38: VARMAN | E38: =19+15 -> 34 | F38: 75000 | G38: =+E38*F38 -> 2550000 | H38: 100000
A39: 46150 | B39: VRM038 | C39: NEW BALANCE 530 BLANCO PLATEADO | D39: VARMAN | E39: 26 | F39: 75000 | G39: =+E39*F39 -> 1950000 | H39: 100000
A40: 46150 | B40: VRM039 | C40: NEW BALANCE 574 GRIS | D40: VARMAN | E40: 3 | F40: 100000 | G40: =+E40*F40 -> 300000 | H40: =+F40+20000 -> 120000
A41: 46150 | B41: VRM040 | C41: NEW BALANCE 9060 BEIGE | D41: VARMAN | E41: 5 | F41: 80000 | G41: =+E41*F41 -> 400000 | H41: =+F41+20000 -> 100000
A42: 46150 | B42: VRM041 | C42: NEW BALANCE 9060 CAFÉ | D42: VARMAN | E42: 2 | F42: 80000 | G42: =+E42*F42 -> 160000 | H42: =+F42+20000 -> 100000
A43: 46150 | B43: VRM042 | C43: NEW BALANCE 9060 FULL NEGRO | D43: VARMAN | E43: 12 | F43: 85000 | G43: =+E43*F43 -> 1020000 | H43: =+F43+20000 -> 105000
A44: 46150 | B44: VRM043 | C44: NEW BALANCE 9060 GRIS | D44: VARMAN | E44: 4 | F44: 80000 | G44: =+E44*F44 -> 320000 | H44: =+F44+20000 -> 100000
A45: 46150 | B45: VRM044 | C45: NEW BALANCE 9060 NEGRO BLANCO | D45: VARMAN | E45: 14 | F45: 90000 | G45: =+E45*F45 -> 1260000 | H45: =+F45+20000 -> 110000
A46: 46150 | B46: VRM045 | C46: NEW BALANCE 990 CAFÉ | D46: VARMAN | E46: 3 | F46: 100000 | G46: =+E46*F46 -> 300000 | H46: =+F46+20000 -> 120000
A47: 46150 | B47: VRM046 | C47: NEW BALANCE 990 GRIS | D47: VARMAN | E47: 3 | F47: 100000 | G47: =+E47*F47 -> 300000 | H47: =+F47+20000 -> 120000
A48: 46150 | B48: VRM047 | C48: NEW BALANCE 990 GRIS NEGRO | D48: VARMAN | E48: 3 | F48: 100000 | G48: =+E48*F48 -> 300000 | H48: =+F48+20000 -> 120000
A49: 46150 | B49: VRM048 | C49: NEW BALANCE ELITE BLANCO VERDE | D49: VARMAN | E49: 9 | F49: 80000 | G49: =+E49*F49 -> 720000 | H49: =+F49+20000 -> 100000
...

Sheet INVENTARIO
A1: CÓDIGO | B1: DESCRIPCIÓN | C1: INV INICIAL | D1: VENTAS | E1: CANTIDAD | F1: VLR COMPRA | G1: VLR BODEGA
A2: VRM001 | B2: =+VLOOKUP(A2,ENTRADAS!$B:$G,2,FALSE) -> ADIDAS ADISTAR NEGRO BLANCO | C2: =+SUMIF(ENTRADAS!B:B,A2,ENTRADAS!E:E) -> 11 | D2: =+SUMIF(VENTAS!C:C,INVENTARIO!A2,VENTAS!B:B) -> 2 | E2: =+C2-D2 -> 9 | F2: =+VLOOKUP(A2,ENTRADAS,5,0) -> 85000 | G2: =+E2*F2 -> 765000 | I2: VLR TOTAL EN BODEGA | J2: =+SUM(G:G) -> 79079000
A3: VRM002 | B3: =+VLOOKUP(A3,ENTRADAS!$B:$G,2,FALSE) -> ADIDAS ADIZERO SL CAFÉ AZUL | C3: =+SUMIF(ENTRADAS!B:B,A3,ENTRADAS!E:E) -> 11 | D3: =+SUMIF(VENTAS!C:C,INVENTARIO!A3,VENTAS!B:B) -> 3 | E3: =+C3-D3 -> 8 | F3: =+VLOOKUP(A3,ENTRADAS,5,0) -> 85000 | G3: =+E3*F3 -> 680000 | I3: UND EN BODEGA | J3: =+SUM(E:E) -> 912
A4: VRM003 | B4: =+VLOOKUP(A4,ENTRADAS!$B:$G,2,FALSE) -> ADIDAS BOUNCE GRIS | C4: =+SUMIF(ENTRADAS!B:B,A4,ENTRADAS!E:E) -> 12 | D4: =+SUMIF(VENTAS!C:C,INVENTARIO!A4,VENTAS!B:B) -> 1 | E4: =+C4-D4 -> 11 | F4: =+VLOOKUP(A4,ENTRADAS,5,0) -> 80000 | G4: =+E4*F4 -> 880000
A5: VRM004 | B5: =+VLOOKUP(A5,ENTRADAS!$B:$G,2,FALSE) -> ADIDAS GAZELLE BEIGE VERDE | C5: =+SUMIF(ENTRADAS!B:B,A5,ENTRADAS!E:E) -> 5 | D5: =+SUMIF(VENTAS!C:C,INVENTARIO!A5,VENTAS!B:B) -> 0 | E5: =+C5-D5 -> 5 | F5: =+VLOOKUP(A5,ENTRADAS,5,0) -> 80000 | G5: =+E5*F5 -> 400000
A6: VRM005 | B6: =+VLOOKUP(A6,ENTRADAS!$B:$G,2,FALSE) -> ADIDAS LED AZUL NEGRO | C6: =+SUMIF(ENTRADAS!B:B,A6,ENTRADAS!E:E) -> 13 | D6: =+SUMIF(VENTAS!C:C,INVENTARIO!A6,VENTAS!B:B) -> 8 | E6: =+C6-D6 -> 5 | F6: =+VLOOKUP(A6,ENTRADAS,5,0) -> 85000 | G6: =+E6*F6 -> 425000
A7: VRM006 | B7: =+VLOOKUP(A7,ENTRADAS!$B:$G,2,FALSE) -> ADIDAS NAS TASE BLANCO AZUL | C7: =+SUMIF(ENTRADAS!B:B,A7,ENTRADAS!E:E) -> 23 | D7: =+SUMIF(VENTAS!C:C,INVENTARIO!A7,VENTAS!B:B) -> 8 | E7: =+C7-D7 -> 15 | F7: =+VLOOKUP(A7,ENTRADAS,5,0) -> 80000 | G7: =+E7*F7 -> 1200000
A8: VRM007 | B8: =+VLOOKUP(A8,ENTRADAS!$B:$G,2,FALSE) -> ADIDAS PUREBOOST NEGRO BLANCO | C8: =+SUMIF(ENTRADAS!B:B,A8,ENTRADAS!E:E) -> 36 | D8: =+SUMIF(VENTAS!C:C,INVENTARIO!A8,VENTAS!B:B) -> 7 | E8: =+C8-D8 -> 29 | F8: =+VLOOKUP(A8,ENTRADAS,5,0) -> 85000 | G8: =+E8*F8 -> 2465000
A9: VRM008 | B9: =+VLOOKUP(A9,ENTRADAS!$B:$G,2,FALSE) -> ADIDAS SAMBA BLANCA CLASICA | C9: =+SUMIF(ENTRADAS!B:B,A9,ENTRADAS!E:E) -> 23 | D9: =+SUMIF(VENTAS!C:C,INVENTARIO!A9,VENTAS!B:B) -> 11 | E9: =+C9-D9 -> 12 | F9: =+VLOOKUP(A9,ENTRADAS,5,0) -> 70000 | G9: =+E9*F9 -> 840000
A10: VRM009 | B10: =+VLOOKUP(A10,ENTRADAS!$B:$G,2,FALSE) -> ADIDAS SAMBA CLASICA NEGRO | C10: =+SUMIF(ENTRADAS!B:B,A10,ENTRADAS!E:E) -> 22 | D10: =+SUMIF(VENTAS!C:C,INVENTARIO!A10,VENTAS!B:B) -> 6 | E10: =+C10-D10 -> 16 | F10: =+VLOOKUP(A10,ENTRADAS,5,0) -> 70000 | G10: =+E10*F10 -> 1120000
A11: VRM010 | B11: =+VLOOKUP(A11,ENTRADAS!$B:$G,2,FALSE) -> ADIDAS SAMBA PLATAFORMA BLANCO VERDE | C11: =+SUMIF(ENTRADAS!B:B,A11,ENTRADAS!E:E) -> 9 | D11: =+SUMIF(VENTAS!C:C,INVENTARIO!A11,VENTAS!B:B) -> 5 | E11: =+C11-D11 -> 4 | F11: =+VLOOKUP(A11,ENTRADAS,5,0) -> 80000 | G11: =+E11*F11 -> 320000
A12: VRM011 | B12: =+VLOOKUP(A12,ENTRADAS!$B:$G,2,FALSE) -> ADIDAS SPEZIAL VERDE ROSADO | C12: =+SUMIF(ENTRADAS!B:B,A12,ENTRADAS!E:E) -> 7 | D12: =+SUMIF(VENTAS!C:C,INVENTARIO!A12,VENTAS!B:B) -> 3 | E12: =+C12-D12 -> 4 | F12: =+VLOOKUP(A12,ENTRADAS,5,0) -> 80000 | G12: =+E12*F12 -> 320000
A13: VRM012 | B13: =+VLOOKUP(A13,ENTRADAS!$B:$G,2,FALSE) -> ADIDAS SPEZIAL VINOTINTO | C13: =+SUMIF(ENTRADAS!B:B,A13,ENTRADAS!E:E) -> 10 | D13: =+SUMIF(VENTAS!C:C,INVENTARIO!A13,VENTAS!B:B) -> 6 | E13: =+C13-D13 -> 4 | F13: =+VLOOKUP(A13,ENTRADAS,5,0) -> 85000 | G13: =+E13*F13 -> 340000
A14: VRM013 | B14: =+VLOOKUP(A14,ENTRADAS!$B:$G,2,FALSE) -> ADIDAS SUPER STAR ADICOLOR | C14: =+SUMIF(ENTRADAS!B:B,A14,ENTRADAS!E:E) -> 5 | D14: =+SUMIF(VENTAS!C:C,INVENTARIO!A14,VENTAS!B:B) -> 0 | E14: =+C14-D14 -> 5 | F14: =+VLOOKUP(A14,ENTRADAS,5,0) -> 80000 | G14: =+E14*F14 -> 400000
A15: VRM014 | B15: =+VLOOKUP(A15,ENTRADAS!$B:$G,2,FALSE) -> ADIDAS SUPER STAR BLESSD | C15: =+SUMIF(ENTRADAS!B:B,A15,ENTRADAS!E:E) -> 5 | D15: =+SUMIF(VENTAS!C:C,INVENTARIO!A15,VENTAS!B:B) -> 0 | E15: =+C15-D15 -> 5 | F15: =+VLOOKUP(A15,ENTRADAS,5,0) -> 80000 | G15: =+E15*F15 -> 400000
... A39: VRM038 | B39: =+VLOOKUP(A39,ENTRADAS!$B:$G,2,FALSE) -> NEW BALANCE 530 BLANCO PLATEADO | C39: =+SUMIF(ENTRADAS!B:B,A39,ENTRADAS!E:E) -> 26 | D39: =+SUMIF(VENTAS!C:C,INVENTARIO!A39,VENTAS!B:B) -> 11 | E39: =+C39-D39 -> 15 | F39: =+VLOOKUP(A39,ENTRADAS,5,0) -> 75000 | G39: =+E39*F39 -> 1125000
A40: VRM039 | B40: =+VLOOKUP(A40,ENTRADAS!$B:$G,2,FALSE) -> NEW BALANCE 574 GRIS | C40: 4 | D40: =+SUMIF(VENTAS!C:C,INVENTARIO!A40,VENTAS!B:B) -> 1 | E40: =+C40-D40 -> 3 | F40: =+VLOOKUP(A40,ENTRADAS,5,0) -> 100000 | G40: =+E40*F40 -> 300000
A41: VRM040 | B41: =+VLOOKUP(A41,ENTRADAS!$B:$G,2,FALSE) -> NEW BALANCE 9060 BEIGE | C41: =+SUMIF(ENTRADAS!B:B,A41,ENTRADAS!E:E) -> 5 | D41: =+SUMIF(VENTAS!C:C,INVENTARIO!A41,VENTAS!B:B) -> 1 | E41: =+C41-D41 -> 4 | F41: =+VLOOKUP(A41,ENTRADAS,5,0) -> 80000 | G41: =+E41*F41 -> 320000
A42: VRM041 | B42: =+VLOOKUP(A42,ENTRADAS!$B:$G,2,FALSE) -> NEW BALANCE 9060 CAFÉ | C42: =+SUMIF(ENTRADAS!B:B,A42,ENTRADAS!E:E) -> 2 | D42: =+SUMIF(VENTAS!C:C,INVENTARIO!A42,VENTAS!B:B) -> 2 | E42: =+C42-D42 -> 0 | F42: =+VLOOKUP(A42,ENTRADAS,5,0) -> 80000 | G42: =+E42*F42 -> 0
A43: VRM042 | B43: =+VLOOKUP(A43,ENTRADAS!$B:$G,2,FALSE) -> NEW BALANCE 9060 FULL NEGRO | C43: =+SUMIF(ENTRADAS!B:B,A43,ENTRADAS!E:E) -> 12 | D43: =+SUMIF(VENTAS!C:C,INVENTARIO!A43,VENTAS!B:B) -> 1 | E43: =+C43-D43 -> 11 | F43: =+VLOOKUP(A43,ENTRADAS,5,0) -> 85000 | G43: =+E43*F43 -> 935000
A44: VRM043 | B44: =+VLOOKUP(A44,ENTRADAS!$B:$G,2,FALSE) -> NEW BALANCE 9060 GRIS | C44: =+SUMIF(ENTRADAS!B:B,A44,ENTRADAS!E:E) -> 4 | D44: =+SUMIF(VENTAS!C:C,INVENTARIO!A44,VENTAS!B:B) -> 0 | E44: =+C44-D44 -> 4 | F44: =+VLOOKUP(A44,ENTRADAS,5,0) -> 80000 | G44: =+E44*F44 -> 320000
A45: VRM044 | B45: =+VLOOKUP(A45,ENTRADAS!$B:$G,2,FALSE) -> NEW BALANCE 9060 NEGRO BLANCO | C45: =+SUMIF(ENTRADAS!B:B,A45,ENTRADAS!E:E) -> 14 | D45: =+SUMIF(VENTAS!C:C,INVENTARIO!A45,VENTAS!B:B) -> 3 | E45: =+C45-D45 -> 11 | F45: =+VLOOKUP(A45,ENTRADAS,5,0) -> 90000 | G45: =+E45*F45 -> 990000
A46: VRM045 | B46: =+VLOOKUP(A46,ENTRADAS!$B:$G,2,FALSE) -> NEW BALANCE 990 CAFÉ | C46: =+SUMIF(ENTRADAS!B:B,A46,ENTRADAS!E:E) -> 3 | D46: =+SUMIF(VENTAS!C:C,INVENTARIO!A46,VENTAS!B:B) -> 1 | E46: =+C46-D46 -> 2 | F46: =+VLOOKUP(A46,ENTRADAS,5,0) -> 100000 | G46: =+E46*F46 -> 200000
A47: VRM046 | B47: =+VLOOKUP(A47,ENTRADAS!$B:$G,2,FALSE) -> NEW BALANCE 990 GRIS | C47: =+SUMIF(ENTRADAS!B:B,A47,ENTRADAS!E:E) -> 3 | D47: =+SUMIF(VENTAS!C:C,INVENTARIO!A47,VENTAS!B:B) -> 0 | E47: =+C47-D47 -> 3 | F47: =+VLOOKUP(A47,ENTRADAS,5,0) -> 100000 | G47: =+E47*F47 -> 300000
A48: VRM047 | B48: =+VLOOKUP(A48,ENTRADAS!$B:$G,2,FALSE) -> NEW BALANCE 990 GRIS NEGRO | C48: =+SUMIF(ENTRADAS!B:B,A48,ENTRADAS!E:E) -> 3 | D48: =+SUMIF(VENTAS!C:C,INVENTARIO!A48,VENTAS!B:B) -> 0 | E48: =+C48-D48 -> 3 | F48: =+VLOOKUP(A48,ENTRADAS,5,0) -> 100000 | G48: =+E48*F48 -> 300000
A49: VRM048 | B49: =+VLOOKUP(A49,ENTRADAS!$B:$G,2,FALSE) -> NEW BALANCE ELITE BLANCO VERDE | C49: =+SUMIF(ENTRADAS!B:B,A49,ENTRADAS!E:E) -> 9 | D49: =+SUMIF(VENTAS!C:C,INVENTARIO!A49,VENTAS!B:B) -> 0 | E49: =+C49-D49 -> 9 | F49: =+VLOOKUP(A49,ENTRADAS,5,0) -> 80000 | G49: =+E49*F49 -> 720000
A50: VRM049 | B50: =+VLOOKUP(A50,ENTRADAS!$B:$G,2,FALSE) -> NEW BALANCE MIU MIU | C50: =+SUMIF(ENTRADAS!B:B,A50,ENTRADAS!E:E) -> 15 | D50: =+SUMIF(VENTAS!C:C,INVENTARIO!A50,VENTAS!B:B) -> 1 | E50: =+C50-D50 -> 14 | F50: =+VLOOKUP(A50,ENTRADAS,5,0) -> 80000 | G50: =+E50*F50 -> 1120000
A51: VRM050 | B51: =+VLOOKUP(A51,ENTRADAS!$B:$G,2,FALSE) -> NIKE CORTEZ VERDE ROSADO | C51: =+SUMIF(ENTRADAS!B:B,A51,ENTRADAS!E:E) -> 11 | D51: =+SUMIF(VENTAS!C:C,INVENTARIO!A51,VENTAS!B:B) -> 0 | E51: =+C51-D51 -> 11 | F51: =+VLOOKUP(A51,ENTRADAS,5,0) -> 80000 | G51: =+E51*F51 -> 880000
A52: VRM051 | B52: =+VLOOKUP(A52,ENTRADAS!$B:$G,2,FALSE) -> NIKE AF1 HIGTH BLANCA | C52: =+SUMIF(ENTRADAS!B:B,A52,ENTRADAS!E:E) -> 9 | D52: =+SUMIF(VENTAS!C:C,INVENTARIO!A52,VENTAS!B:B) -> 4 | E52: =+C52-D52 -> 5 | F52: =+VLOOKUP(A52,ENTRADAS,5,0) -> 85000 | G52: =+E52*F52 -> 425000
... A81: VRM080 | B81: =+VLOOKUP(A81,ENTRADAS!$B:$G,2,FALSE) -> ADIDAS BOUNCE AZUL BLANCO | C81: =+SUMIF(ENTRADAS!B:B,A81,ENTRADAS!E:E) -> 3 | D81: =+SUMIF(VENTAS!C:C,INVENTARIO!A81,VENTAS!B:B) -> 2 | E81: =+C81-D81 -> 1 | F81: =+VLOOKUP(A81,ENTRADAS,5,0) -> 80000 | G81: =+E81*F81 -> 80000

Sheet VENTAS
A1: FECHA | B1: CANTIDAD | C1: CÓDIGO | D1: DESCRIPCIÓN | E1: VLR VENTA
A2: 46150 | B2: 1 | C2: VRM061 | D2: =+VLOOKUP(C2,ENTRADAS!B:C,2,0) -> NIKE SB BLANCO MORADO | E2: =+VLOOKUP(C2,ENTRADAS!B:H,7,0) -> 105000
A3: 46150 | B3: 1 | C3: VRM032 | D3: =+VLOOKUP(C3,ENTRADAS!B:C,2,0) -> LOUIS VUITTON G5 GRIS | E3: =+VLOOKUP(C3,ENTRADAS!B:H,7,0) -> 200000
A4: 46150 | B4: 1 | C4: VRM069 | D4: =+VLOOKUP(C4,ENTRADAS!B:C,2,0) -> SKECHERS DLITES NEGRA | E4: =+VLOOKUP(C4,ENTRADAS!B:H,7,0) -> 105000
A5: 46150 | B5: 1 | C5: VRM007 | D5: =+VLOOKUP(C5,ENTRADAS!B:C,2,0) -> ADIDAS PUREBOOST NEGRO BLANCO | E5: =+VLOOKUP(C5,ENTRADAS!B:H,7,0) -> 105000
A6: 46150 | B6: 1 | C6: VRM032 | D6: =+VLOOKUP(C6,ENTRADAS!B:C,2,0) -> LOUIS VUITTON G5 GRIS | E6: =+VLOOKUP(C6,ENTRADAS!B:H,7,0) -> 200000
A7: 46150 | B7: 1 | C7: VRM009 | D7: =+VLOOKUP(C7,ENTRADAS!B:C,2,0) -> ADIDAS SAMBA CLASICA NEGRO | E7: =+VLOOKUP(C7,ENTRADAS!B:H,7,0) -> 90000
A8: 46150 | B8: 1 | C8: VRM009 | D8: =+VLOOKUP(C8,ENTRADAS!B:C,2,0) -> ADIDAS SAMBA CLASICA NEGRO | E8: =+VLOOKUP(C8,ENTRADAS!B:H,7,0) -> 90000
A9: 46150 | B9: 1 | C9: VRM012 | D9: =+VLOOKUP(C9,ENTRADAS!B:C,2,0) -> ADIDAS SPEZIAL VINOTINTO | E9: =+VLOOKUP(C9,ENTRADAS!B:H,7,0) -> 105000
A10: 46151 | B10: 1 | C10: VRM062 | D10: =+VLOOKUP(C10,ENTRADAS!B:C,2,0) -> NIKE SB VERDE OLIVA | E10: 110000
A11: 46151 | B11: 1 | C11: VRM070 | D11: =+VLOOKUP(C11,ENTRADAS!B:C,2,0) -> SKECHERS ONE BLANCO | E11: =+VLOOKUP(C11,ENTRADAS!B:H,7,0) -> 105000
A12: 46151 | B12: 1 | C12: VRM009 | D12: =+VLOOKUP(C12,ENTRADAS!B:C,2,0) -> ADIDAS SAMBA CLASICA NEGRO | E12: =+VLOOKUP(C12,ENTRADAS!B:H,7,0) -> 90000
A13: 46151 | B13: 1 | C13: VRM038 | D13: =+VLOOKUP(C13,ENTRADAS!B:C,2,0) -> NEW BALANCE 530 BLANCO PLATEADO | E13: 100000
A14: 46151 | B14: 1 | C14: VRM060 | D14: =+VLOOKUP(C14,ENTRADAS!B:C,2,0) -> NIKE FREE NEGRO BLANCO | E14: =+VLOOKUP(C14,ENTRADAS!B:H,7,0) -> 100000
A15: 46151 | B15: 1 | C15: VRM064 | D15: =+VLOOKUP(C15,ENTRADAS!B:C,2,0) -> NIKE TN FULL NEGRO | E15: 100000
A16: 46151 | B16: 1 | C16: VRM061 | D16: =+VLOOKUP(C16,ENTRADAS!B:C,2,0) -> NIKE SB BLANCO MORADO | E16: =+VLOOKUP(C16,ENTRADAS!B:H,7,0) -> 105000
A17: 46151 | B17: 1 | C17: VRM061 | D17: =+VLOOKUP(C17,ENTRADAS!B:C,2,0) -> NIKE SB BLANCO MORADO | E17: =+VLOOKUP(C17,ENTRADAS!B:H,7,0) -> 105000
A18: 46152 | B18: 1 | C18: VRM051 | D18: =+VLOOKUP(C18,ENTRADAS!B:C,2,0) -> NIKE AF1 HIGTH BLANCA | E18: 100000
A19: 46152 | B19: 1 | C19: VRM033 | D19: =+VLOOKUP(C19,ENTRADAS!B:C,2,0) -> LOUIS VUITTON G5 NEGRA | E19: =+VLOOKUP(C19,ENTRADAS!B:H,7,0) -> 200000
A20: 46152 | B20: 1 | C20: VRM062 | D20: =+VLOOKUP(C20,ENTRADAS!B:C,2,0) -> NIKE SB VERDE OLIVA | E20: =+VLOOKUP(C20,ENTRADAS!B:H,7,0) -> 100000
A21: 46152 | B21: 1 | C21: VRM033 | D21: =+VLOOKUP(C21,ENTRADAS!B:C,2,0) -> LOUIS VUITTON G5 NEGRA | E21: =+VLOOKUP(C21,ENTRADAS!B:H,7,0) -> 200000
A22: 46153 | B22: 1 | C22: VRM007 | D22: =+VLOOKUP(C22,ENTRADAS!B:C,2,0) -> ADIDAS PUREBOOST NEGRO BLANCO | E22: =+VLOOKUP(C22,ENTRADAS!B:H,7,0) -> 105000
A23: 46153 | B23: 1 | C23: VRM008 | D23: =+VLOOKUP(C23,ENTRADAS!B:C,2,0) -> ADIDAS SAMBA BLANCA CLASICA | E23: =+VLOOKUP(C23,ENTRADAS!B:H,7,0) -> 90000
A24: 46153 | B24: 1 | C24: VRM038 | D24: =+VLOOKUP(C24,ENTRADAS!B:C,2,0) -> NEW BALANCE 530 BLANCO PLATEADO | E24: =+VLOOKUP(C24,ENTRADAS!B:H,7,0) -> 100000
A25: 46153 | B25: 1 | C25: VRM033 | D25: =+VLOOKUP(C25,ENTRADAS!B:C,2,0) -> LOUIS VUITTON G5 NEGRA | E25: =+VLOOKUP(C25,ENTRADAS!B:H,7,0) -> 200000
A26: 46154 | B26: 1 | C26: VRM039 | D26: =+VLOOKUP(C26,ENTRADAS!B:C,2,0) -> NEW BALANCE 574 GRIS | E26: 100000
A27: 46154 | B27: 1 | C27: VRM033 | D27: =+VLOOKUP(C27,ENTRADAS!B:C,2,0) -> LOUIS VUITTON G5 NEGRA | E27: =+VLOOKUP(C27,ENTRADAS!B:H,7,0) -> 200000
A28: 46154 | B28: 1 | C28: VRM032 | D28: =+VLOOKUP(C28,ENTRADAS!B:C,2,0) -> LOUIS VUITTON G5 GRIS | E28: =+VLOOKUP(C28,ENTRADAS!B:H,7,0) -> 200000
A29: 46154 | B29: 1 | C29: VRM016 | D29: =+VLOOKUP(C29,ENTRADAS!B:C,2,0) -> ADIDAS TERREX VERDE NARANJA | E29: =+VLOOKUP(C29,ENTRADAS!B:H,7,0) -> 110000
A30: 46154 | B30: 1 | C30: VRM008 | D30: =+VLOOKUP(C30,ENTRADAS!B:C,2,0) -> ADIDAS SAMBA BLANCA CLASICA | E30: =+VLOOKUP(C30,ENTRADAS!B:H,7,0) -> 90000
A31: 46154 | B31: 1 | C31: VRM052 | D31: =+VLOOKUP(C31,ENTRADAS!B:C,2,0) -> NIKE AF1 LOW BLANCO | E31: =+VLOOKUP(C31,ENTRADAS!B:H,7,0) -> 90000
A32: 46154 | B32: 1 | C32: VRM037 | D32: =+VLOOKUP(C32,ENTRADAS!B:C,2,0) -> NEW BALANCE 530 BLANCO AZUL | E32: 90000
A33: 46155 | B33: 1 | C33: VRM009 | D33: =+VLOOKUP(C33,ENTRADAS!B:C,2,0) -> ADIDAS SAMBA CLASICA NEGRO | E33: =+VLOOKUP(C33,ENTRADAS!B:H,7,0) -> 90000
A34: 46155 | B34: 1 | C34: VRM044 | D34: =+VLOOKUP(C34,ENTRADAS!B:C,2,0) -> NEW BALANCE 9060 NEGRO BLANCO | E34: =+VLOOKUP(C34,ENTRADAS!B:H,7,0) -> 110000
A35: 46155 | B35: 6 | C35: VRM006 | D35: =+VLOOKUP(C35,ENTRADAS!B:C,2,0) -> ADIDAS NAS TASE BLANCO AZUL | E35: 600000
A36: 46155 | B36: 1 | C36: VRM008 | D36: =+VLOOKUP(C36,ENTRADAS!B:C,2,0) -> ADIDAS SAMBA BLANCA CLASICA | E36: =+VLOOKUP(C36,ENTRADAS!B:H,7,0) -> 90000
A37: 46155 | B37: 1 | C37: VRM023 | D37: =+VLOOKUP(C37,ENTRADAS!B:C,2,0) -> FILA RAY BEIGE MORADO | E37: =+VLOOKUP(C37,ENTRADAS!B:H,7,0) -> 105000
A38: 46156 | B38: 1 | C38: VRM066 | D38: =+VLOOKUP(C38,ENTRADAS!B:C,2,0) -> NIKE VOMERO 5 BLANCO PLATEADO | E38: =+VLOOKUP(C38,ENTRADAS!B:H,7,0) -> 100000
A39: 46156 | B39: 1 | C39: VRM038 | D39: =+VLOOKUP(C39,ENTRADAS!B:C,2,0) -> NEW BALANCE 530 BLANCO PLATEADO | E39: =+VLOOKUP(C39,ENTRADAS!B:H,7,0) -> 100000
A40: 46156 | B40: 1 | C40: VRM038 | D40: =+VLOOKUP(C40,ENTRADAS!B:C,2,0) -> NEW BALANCE 530 BLANCO PLATEADO | E40: =+VLOOKUP(C40,ENTRADAS!B:H,7,0) -> 100000
...
